(.venv) PS C:\Users\Артем\PycharmProjects\homework_10_djan\quotes> python manage.py migrate
Operations to perform:
  Apply all migrations: admin, auth, contenttypes, quoteapp, sessions, users
Running migrations:
  Applying quoteapp.0003_rename_user_author_user_id_rename_user_quote_user_id...Traceback (most recent call last):
  File "C:\Users\Артем\PycharmProjects\homework_10_djan\.venv\Lib\site-packages\django\db\backends\utils.py", line 103, in _execute
    return self.cursor.execute(sql)
           ^^^^^^^^^^^^^^^^^^^^^^^^
psycopg2.errors.UndefinedColumn: column "user_id" does not exist


The above exception was the direct cause of the following exception:

Traceback (most recent call last):
  File "C:\Users\Артем\PycharmProjects\homework_10_djan\quotes\manage.py", line 22, in <module>
    main()
  File "C:\Users\Артем\PycharmProjects\homework_10_djan\quotes\manage.py", line 18, in main
    execute_from_command_line(sys.argv)
  File "C:\Users\Артем\PycharmProjects\homework_10_djan\.venv\Lib\site-packages\django\core\management\__init__.py", line 442, in execute_from_command_line
    utility.execute()
  File "C:\Users\Артем\PycharmProjects\homework_10_djan\.venv\Lib\site-packages\django\core\management\__init__.py", line 436, in execute
    self.fetch_command(subcommand).run_from_argv(self.argv)
  File "C:\Users\Артем\PycharmProjects\homework_10_djan\.venv\Lib\site-packages\django\core\management\base.py", line 413, in run_from_argv
    self.execute(*args, **cmd_options)
  File "C:\Users\Артем\PycharmProjects\homework_10_djan\.venv\Lib\site-packages\django\core\management\base.py", line 459, in execute
    output = self.handle(*args, **options)
             ^^^^^^^^^^^^^^^^^^^^^^^^^^^^^
  File "C:\Users\Артем\PycharmProjects\homework_10_djan\.venv\Lib\site-packages\django\core\management\base.py", line 107, in wrapper
    res = handle_func(*args, **kwargs)
          ^^^^^^^^^^^^^^^^^^^^^^^^^^^^
  File "C:\Users\Артем\PycharmProjects\homework_10_djan\.venv\Lib\site-packages\django\core\management\commands\migrate.py", line 356, in handle
    post_migrate_state = executor.migrate(
                         ^^^^^^^^^^^^^^^^^
  File "C:\Users\Артем\PycharmProjects\homework_10_djan\.venv\Lib\site-packages\django\db\migrations\executor.py", line 135, in migrate
    state = self._migrate_all_forwards(
            ^^^^^^^^^^^^^^^^^^^^^^^^^^^
  File "C:\Users\Артем\PycharmProjects\homework_10_djan\.venv\Lib\site-packages\django\db\migrations\executor.py", line 167, in _migrate_all_forwards
    state = self.apply_migration(
            ^^^^^^^^^^^^^^^^^^^^^
  File "C:\Users\Артем\PycharmProjects\homework_10_djan\.venv\Lib\site-packages\django\db\migrations\executor.py", line 252, in apply_migration
    state = migration.apply(state, schema_editor)
            ^^^^^^^^^^^^^^^^^^^^^^^^^^^^^^^^^^^^^
  File "C:\Users\Артем\PycharmProjects\homework_10_djan\.venv\Lib\site-packages\django\db\migrations\migration.py", line 132, in apply
    operation.database_forwards(
  File "C:\Users\Артем\PycharmProjects\homework_10_djan\.venv\Lib\site-packages\django\db\migrations\operations\fields.py", line 303, in database_forwards
    schema_editor.alter_field(
  File "C:\Users\Артем\PycharmProjects\homework_10_djan\.venv\Lib\site-packages\django\db\backends\base\schema.py", line 885, in alter_field
    self._alter_field(
  File "C:\Users\Артем\PycharmProjects\homework_10_djan\.venv\Lib\site-packages\django\db\backends\postgresql\schema.py", line 288, in _alter_field
    super()._alter_field(
  File "C:\Users\Артем\PycharmProjects\homework_10_djan\.venv\Lib\site-packages\django\db\backends\base\schema.py", line 1050, in _alter_field
    self.execute(
  File "C:\Users\Артем\PycharmProjects\homework_10_djan\.venv\Lib\site-packages\django\db\backends\postgresql\schema.py", line 48, in execute
    return super().execute(sql, None)
           ^^^^^^^^^^^^^^^^^^^^^^^^^^
  File "C:\Users\Артем\PycharmProjects\homework_10_djan\.venv\Lib\site-packages\django\db\backends\base\schema.py", line 201, in execute
    cursor.execute(sql, params)
  File "C:\Users\Артем\PycharmProjects\homework_10_djan\.venv\Lib\site-packages\django\db\backends\utils.py", line 122, in execute
    return super().execute(sql, params)
           ^^^^^^^^^^^^^^^^^^^^^^^^^^^^
  File "C:\Users\Артем\PycharmProjects\homework_10_djan\.venv\Lib\site-packages\django\db\backends\utils.py", line 79, in execute
    return self._execute_with_wrappers(
           ^^^^^^^^^^^^^^^^^^^^^^^^^^^^
  File "C:\Users\Артем\PycharmProjects\homework_10_djan\.venv\Lib\site-packages\django\db\backends\utils.py", line 92, in _execute_with_wrappers
    return executor(sql, params, many, context)
           ^^^^^^^^^^^^^^^^^^^^^^^^^^^^^^^^^^^^
  File "C:\Users\Артем\PycharmProjects\homework_10_djan\.venv\Lib\site-packages\django\db\backends\utils.py", line 100, in _execute
    with self.db.wrap_database_errors:
  File "C:\Users\Артем\PycharmProjects\homework_10_djan\.venv\Lib\site-packages\django\db\utils.py", line 91, in __exit__
    raise dj_exc_value.with_traceback(traceback) from exc_value
  File "C:\Users\Артем\PycharmProjects\homework_10_djan\.venv\Lib\site-packages\django\db\backends\utils.py", line 103, in _execute
    return self.cursor.execute(sql)
           ^^^^^^^^^^^^^^^^^^^^^^^^
django.db.utils.ProgrammingError: column "user_id" does not exist
